Workbook
Name NativeTimeline_Order_Date: #N/A
Name Slicer_Category: #N/A
Name Slicer_District: #N/A
Name Slicer_Order_Status: #N/A
Name Slicer_Payment_Method: #N/A
Name Slicer_Sales_Channel: #N/A

Sheet Ecommerce_Data
A1: Order_ID | B1: Customer_ID | C1: Order_Date | D1: City | E1: District | F1: Gender | G1: Customer_Age | H1: Age_Group | I1: Category | J1: Product | K1: Quantity | L1: Unit_Price_INR | M1: Discount | N1: Discount % | O1: Discount_Amount_INR | P1: Order_Value_INR | Q1: Shipping_Charge_INR | R1: Total_Amount_INR | S1: Payment_Method | T1: Sales_Channel | U1: Order_Status | V1: Delivery_Days | W1: Customer_Rating
A2: TNORD0001 | B2: TNCUST0060 | C2: 45674 | D2: Dindigul | E2: Dindigul | F2: Other | G2: 23 | H2: 56+ | I2: Electronics | J2: Smartphone | K2: 3 | L2: 32898 | M2: 20 | N2: =Table1[[#This Row],[Discount]]/100 -> 0.2 | O2: 19738.8 | P2: 78955.2 | Q2: 128 | R2: 79083.2 | S2: UPI | T2: Marketplace | U2: Delivered | V2: 1 | W2: 3.5
A3: TNORD0002 | B3: TNCUST0072 | C3: 46015 | D3: Tiruchirappalli | E3: Tiruchirappalli | F3: Male | G3: 39 | H3: 26-35 | I3: Sports | J3: Badminton Racket | K3: 4 | L3: 7521 | M3: 0 | N3: =Table1[[#This Row],[Discount]]/100 -> 0 | O3: 0 | P3: 30084 | Q3: 60 | R3: 30144 | S3: Debit Card | T3: Website | U3: Shipped | V3: 4
A4: TNORD0003 | B4: TNCUST0159 | C4: 45698 | D4: Coimbatore | E4: Coimbatore | F4: Female | G4: 36 | H4: 56+ | I4: Grocery | J4: Rice | K4: 3 | L4: 257 | M4: 20 | N4: =Table1[[#This Row],[Discount]]/100 -> 0.2 | O4: 154.2 | P4: 616.8 | Q4: 116 | R4: 732.8 | S4: Credit Card | T4: Marketplace | U4: Delivered | V4: 5 | W4: 5
A5: TNORD0004 | B5: TNCUST0172 | C5: 45847 | D5: Coimbatore | E5: Coimbatore | F5: Female | G5: 31 | H5: 18-25 | I5: Electronics | J5: Laptop | K5: 3 | L5: 11258 | M5: 25 | N5: =Table1[[#This Row],[Discount]]/100 -> 0.25 | O5: 8443.5 | P5: 25330.5 | Q5: 61 | R5: 25391.5 | S5: Net Banking | T5: Marketplace | U5: Processing
A6: TNORD0005 | B6: TNCUST0207 | C6: 45686 | D6: Madurai | E6: Madurai | F6: Female | G6: 20 | H6: 46-55 | I6: Beauty | J6: Shampoo | K6: 2 | L6: 1049 | M6: 10 | N6: =Table1[[#This Row],[Discount]]/100 -> 0.1 | O6: 209.8 | P6: 1888.2 | Q6: 218 | R6: 2106.2 | S6: Debit Card | T6: Website | U6: Processing
A7: TNORD0006 | B7: TNCUST0110 | C7: 45792 | D7: Tiruchirappalli | E7: Tiruchirappalli | F7: Other | G7: 55 | H7: 46-55 | I7: Beauty | J7: Moisturizer | K7: 2 | L7: 1234 | M7: 5 | N7: =Table1[[#This Row],[Discount]]/100 -> 0.05 | O7: 123.4 | P7: 2344.6 | Q7: 157 | R7: 2501.6 | S7: Debit Card | T7: Website | U7: Shipped | V7: 6
A8: TNORD0007 | B8: TNCUST0065 | C8: 45853 | D8: Madurai | E8: Madurai | F8: Other | G8: 47 | H8: 18-25 | I8: Beauty | J8: Sunscreen | K8: 1 | L8: 3394 | M8: 15 | N8: =Table1[[#This Row],[Discount]]/100 -> 0.15 | O8: 509.1 | P8: 2884.9 | Q8: 118 | R8: 3002.9 | S8: Wallet | T8: Marketplace | U8: Delivered | V8: 5 | W8: 4.5
A9: TNORD0008 | B9: TNCUST0130 | C9: 45792 | D9: Coimbatore | E9: Coimbatore | F9: Male | G9: 29 | H9: 36-45 | I9: Sports | J9: Badminton Racket | K9: 3 | L9: 4116 | M9: 0 | N9: =Table1[[#This Row],[Discount]]/100 -> 0 | O9: 0 | P9: 12348 | Q9: 244 | R9: 12592 | S9: Wallet | T9: Marketplace | U9: Returned
A10: TNORD0009 | B10: TNCUST0225 | C10: 45815 | D10: Thanjavur | E10: Thanjavur | F10: Other | G10: 21 | H10: 18-25 | I10: Fashion | J10: Kurta | K10: 3 | L10: 4818 | M10: 15 | N10: =Table1[[#This Row],[Discount]]/100 -> 0.15 | O10: 2168.1 | P10: 12285.9 | Q10: 112 | R10: 12397.9 | S10: UPI | T10: Marketplace | U10: Delivered | V10: 2 | W10: 3.5
A11: TNORD0010 | B11: TNCUST0183 | C11: 45766 | D11: Vellore | E11: Vellore | F11: Female | G11: 30 | H11: 46-55 | I11: Electronics | J11: Power Bank | K11: 2 | L11: 17628 | M11: 20 | N11: =Table1[[#This Row],[Discount]]/100 -> 0.2 | O11: 7051.2 | P11: 28204.8 | Q11: 128 | R11: 28332.8 | S11: Wallet | T11: Marketplace | U11: Cancelled
A12: TNORD0011 | B12: TNCUST0162 | C12: 45770 | D12: Tirunelveli | E12: Tirunelveli | F12: Male | G12: 22 | H12: 26-35 | I12: Grocery | J12: Tea | K12: 4 | L12: 342 | M12: 20 | N12: =Table1[[#This Row],[Discount]]/100 -> 0.2 | O12: 273.6 | P12: 1094.4 | Q12: 170 | R12: 1264.4 | S12: UPI | T12: Website | U12: Delivered | V12: 1 | W12: 5
A13: TNORD0012 | B13: TNCUST0201 | C13: 45953 | D13: Kanchipuram | E13: Kanchipuram | F13: Female | G13: 33 | H13: 46-55 | I13: Home & Kitchen | J13: Mixer Grinder | K13: 5 | L13: 8253 | M13: 25 | N13: =Table1[[#This Row],[Discount]]/100 -> 0.25 | O13: 10316.25 | P13: 30948.75 | Q13: 166 | R13: 31114.75 | S13: Credit Card | T13: Website | U13: Returned
A14: TNORD0013 | B14: TNCUST0050 | C14: 45831 | D14: Coimbatore | E14: Coimbatore | F14: Male | G14: 24 | H14: 56+ | I14: Sports | J14: Running Shoes | K14: 3 | L14: 5753 | M14: 25 | N14: =Table1[[#This Row],[Discount]]/100 -> 0.25 | O14: 4314.75 | P14: 12944.25 | Q14: 123 | R14: 13067.25 | S14: Cash on Delivery | T14: Website | U14: Delivered | V14: 7 | W14: 3.5
A15: TNORD0014 | B15: TNCUST0043 | C15: 45665 | D15: Erode | E15: Erode | F15: Female | G15: 33 | H15: 46-55 | I15: Fashion | J15: T-Shirt | K15: 4 | L15: 1017 | M15: 25 | N15: =Table1[[#This Row],[Discount]]/100 -> 0.25 | O15: 1017 | P15: 3051 | Q15: 234 | R15: 3285 | S15: Cash on Delivery | T15: Website | U15: Returned
A16: TNORD0015 | B16: TNCUST0049 | C16: 45942 | D16: Kanchipuram | E16: Kanchipuram | F16: Female | G16: 49 | H16: 26-35 | I16: Grocery | J16: Rice | K16: 2 | L16: 1166 | M16: 15 | N16: =Table1[[#This Row],[Discount]]/100 -> 0.15 | O16: 349.8 | P16: 1982.2 | Q16: 198 | R16: 2180.2 | S16: UPI | T16: Marketplace | U16: Delivered | V16: 6 | W16: 3.5
A17: TNORD0016 | B17: TNCUST0153 | C17: 45699 | D17: Hosur | E17: Krishnagiri | F17: Male | G17: 29 | H17: 26-35 | I17: Beauty | J17: Face Wash | K17: 3 | L17: 2209 | M17: 20 | N17: =Table1[[#This Row],[Discount]]/100 -> 0.2 | O17: 1325.4 | P17: 5301.6 | Q17: 150 | R17: 5451.6 | S17: Cash on Delivery | T17: Website | U17: Delivered | V17: 7 | W17: 3
A18: TNORD0017 | B18: TNCUST0068 | C18: 45762 | D18: Karur | E18: Karur | F18: Female | G18: 38 | H18: 26-35 | I18: Beauty | J18: Shampoo | K18: 5 | L18: 2842 | M18: 20 | N18: =Table1[[#This Row],[Discount]]/100 -> 0.2 | O18: 2842 | P18: 11368 | Q18: 86 | R18: 11454 | S18: Wallet | T18: Marketplace | U18: Delivered | V18: 6 | W18: 3.5
A19: TNORD0018 | B19: TNCUST0073 | C19: 45836 | D19: Salem | E19: Salem | F19: Male | G19: 33 | H19: 46-55 | I19: Grocery | J19: Spices | K19: 1 | L19: 489 | M19: 5 | N19: =Table1[[#This Row],[Discount]]/100 -> 0.05 | O19: 24.45 | P19: 464.55 | Q19: 53 | R19: 517.55 | S19: Net Banking | T19: Marketplace | U19: Delivered | V19: 1 | W19: 4
A20: TNORD0019 | B20: TNCUST0054 | C20: 45797 | D20: Salem | E20: Salem | F20: Other | G20: 56 | H20: 36-45 | I20: Beauty | J20: Perfume | K20: 1 | L20: 1233 | M20: 0 | N20: =Table1[[#This Row],[Discount]]/100 -> 0 | O20: 0 | P20: 1233 | Q20: 59 | R20: 1292 | S20: Credit Card | T20: Marketplace | U20: Shipped | V20: 3
A21: TNORD0020 | B21: TNCUST0190 | C21: 45724 | D21: Dindigul | E21: Dindigul | F21: Female | G21: 34 | H21: 56+ | I21: Home & Kitchen | J21: Storage Box | K21: 4 | L21: 1812 | M21: 0 | N21: =Table1[[#This Row],[Discount]]/100 -> 0 | O21: 0 | P21: 7248 | Q21: 217 | R21: 7465 | S21: Wallet | T21: Mobile App | U21: Delivered | V21: 6 | W21: 3.5
A22: TNORD0021 | B22: TNCUST0054 | C22: 45815 | D22: Thoothukudi | E22: Thoothukudi | F22: Other | G22: 20 | H22: 26-35 | I22: Electronics | J22: Smartphone | K22: 1 | L22: 20336 | M22: 5 | N22: =Table1[[#This Row],[Discount]]/100 -> 0.05 | O22: 1016.8 | P22: 19319.2 | Q22: 30 | R22: 19349.2 | S22: Wallet | T22: Website | U22: Delivered | V22: 3 | W22: 4
A23: TNORD0022 | B23: TNCUST0208 | C23: 45868 | D23: Tirunelveli | E23: Tirunelveli | F23: Male | G23: 60 | H23: 36-45 | I23: Beauty | J23: Sunscreen | K23: 5 | L23: 3760 | M23: 0 | N23: =Table1[[#This Row],[Discount]]/100 -> 0 | O23: 0 | P23: 18800 | Q23: 105 | R23: 18905 | S23: Credit Card | T23: Marketplace | U23: Delivered | V23: 7 | W23: 5
A24: TNORD0023 | B24: TNCUST0222 | C24: 45756 | D24: Coimbatore | E24: Coimbatore | F24: Male | G24: 39 | H24: 36-45 | I24: Grocery | J24: Rice | K24: 4 | L24: 1512 | M24: 5 | N24: =Table1[[#This Row],[Discount]]/100 -> 0.05 | O24: 302.4 | P24: 5745.6 | Q24: 188 | R24: 5933.6 | S24: Debit Card | T24: Marketplace | U24: Delivered | V24: 4 | W24: 4
A25: TNORD0024 | B25: TNCUST0156 | C25: 45834 | D25: Thoothukudi | E25: Thoothukudi | F25: Other | G25: 38 | H25: 18-25 | I25: Grocery | J25: Tea | K25: 3 | L25: 811 | M25: 0 | N25: =Table1[[#This Row],[Discount]]/100 -> 0 | O25: 0 | P25: 2433 | Q25: 131 | R25: 2564 | S25: Cash on Delivery | T25: Marketplace | U25: Delivered | V25: 6 | W25: 4
A26: TNORD0025 | B26: TNCUST0218 | C26: 45977 | D26: Tiruchirappalli | E26: Tiruchirappalli | F26: Male | G26: 60 | H26: 36-45 | I26: Home & Kitchen | J26: Mixer Grinder | K26: 4 | L26: 9121 | M26: 0 | N26: =Table1[[#This Row],[Discount]]/100 -> 0 | O26: 0 | P26: 36484 | Q26: 104 | R26: 36588 | S26: Net Banking | T26: Mobile App | U26: Returned
A27: TNORD0026 | B27: TNCUST0104 | C27: 45973 | D27: Dindigul | E27: Dindigul | F27: Other | G27: 37 | H27: 18-25 | I27: Grocery | J27: Spices | K27: 4 | L27: 865 | M27: 15 | N27: =Table1[[#This Row],[Discount]]/100 -> 0.15 | O27: 519 | P27: 2941 | Q27: 64 | R27: 3005 | S27: Debit Card | T27: Mobile App | U27: Shipped | V27: 5
A28: TNORD0027 | B28: TNCUST0132 | C28: 45744 | D28: Tiruchirappalli | E28: Tiruchirappalli | F28: Other | G28: 23 | H28: 56+ | I28: Grocery | J28: Tea | K28: 5 | L28: 1891 | M28: 20 | N28: =Table1[[#This Row],[Discount]]/100 -> 0.2 | O28: 1891 | P28: 7564 | Q28: 250 | R28: 7814 | S28: Debit Card | T28: Website | U28: Delivered | V28: 6 | W28: 4
A29: TNORD0028 | B29: TNCUST0148 | C29: 45891 | D29: Kanchipuram | E29: Kanchipuram | F29: Male | G29: 58 | H29: 46-55 | I29: Fashion | J29: T-Shirt | K29: 2 | L29: 1607 | M29: 20 | N29: =Table1[[#This Row],[Discount]]/100 -> 0.2 | O29: 642.8 | P29: 2571.2 | Q29: 38 | R29: 2609.2 | S29: Cash on Delivery | T29: Mobile App | U29: Processing
A30: TNORD0029 | B30: TNCUST0171 | C30: 45720 | D30: Tiruchirappalli | E30: Tiruchirappalli | F30: Other | G30: 26 | H30: 56+ | I30: Fashion | J30: Saree | K30: 1 | L30: 2192 | M30: 20 | N30: =Table1[[#This Row],[Discount]]/100 -> 0.2 | O30: 438.4 | P30: 1753.6 | Q30: 237 | R30: 1990.6 | S30: Net Banking | T30: Mobile App | U30: Delivered | V30: 4 | W30: 4
A31: TNORD0030 | B31: TNCUST0197 | C31: 45784 | D31: Nagercoil | E31: Kanyakumari | F31: Other | G31: 58 | H31: 46-55 | I31: Grocery | J31: Tea | K31: 5 | L31: 731 | M31: 15 | N31: =Table1[[#This Row],[Discount]]/100 -> 0.15 | O31: 548.25 | P31: 3106.75 | Q31: 212 | R31: 3318.75 | S31: Wallet | T31: Website | U31: Delivered | V31: 7 | W31: 4
A32: TNORD0031 | B32: TNCUST0055 | C32: 45854 | D32: Salem | E32: Salem | F32: Male | G32: 27 | H32: 46-55 | I32: Grocery | J32: Rice | K32: 3 | L32: 1389 | M32: 0 | N32: =Table1[[#This Row],[Discount]]/100 -> 0 | O32: 0 | P32: 4167 | Q32: 79 | R32: 4246 | S32: Cash on Delivery | T32: Mobile App | U32: Delivered | V32: 6 | W32: 5
A33: TNORD0032 | B33: TNCUST0138 | C33: 45838 | D33: Thoothukudi | E33: Thoothukudi | F33: Other | G33: 42 | H33: 56+ | I33: Grocery | J33: Snacks | K33: 1 | L33: 2472 | M33: 20 | N33: =Table1[[#This Row],[Discount]]/100 -> 0.2 | O33: 494.4 | P33: 1977.6 | Q33: 21 | R33: 1998.6 | S33: Net Banking | T33: Website | U33: Delivered | V33: 3 | W33: 4
A34: TNORD0033 | B34: TNCUST0137 | C34: 45897 | D34: Vellore | E34: Vellore | F34: Male | G34: 57 | H34: 46-55 | I34: Fashion | J34: T-Shirt | K34: 4 | L34: 637 | M34: 15 | N34: =Table1[[#This Row],[Discount]]/100 -> 0.15 | O34: 382.2 | P34: 2165.8 | Q34: 235 | R34: 2400.8 | S34: Net Banking | T34: Marketplace | U34: Shipped | V34: 2
A35: TNORD0034 | B35: TNCUST0193 | C35: 45830 | D35: Dindigul | E35: Dindigul | F35: Female | G35: 42 | H35: 36-45 | I35: Electronics | J35: Smartphone | K35: 4 | L35: 18586 | M35: 10 | N35: =Table1[[#This Row],[Discount]]/100 -> 0.1 | O35: 7434.4 | P35: 66909.6 | Q35: 103 | R35: 67012.6 | S35: UPI | T35: Mobile App | U35: Delivered | V35: 7 | W35: 4
A36: TNORD0035 | B36: TNCUST0122 | C36: 45976 | D36: Chennai | E36: Chennai | F36: Other | G36: 33 | H36: 18-25 | I36: Sports | J36: Badminton Racket | K36: 1 | L36: 654 | M36: 5 | N36: =Table1[[#This Row],[Discount]]/100 -> 0.05 | O36: 32.7 | P36: 621.3 | Q36: 25 | R36: 646.3 | S36: Net Banking | T36: Website | U36: Delivered | V36: 2 | W36: 3.5
A37: TNORD0036 | B37: TNCUST0242 | C37: 45952 | D37: Vellore | E37: Vellore | F37: Other | G37: 42 | H37: 26-35 | I37: Sports | J37: Yoga Mat | K37: 3 | L37: 1285 | M37: 20 | N37: =Table1[[#This Row],[Discount]]/100 -> 0.2 | O37: 771 | P37: 3084 | Q37: 99 | R37: 3183 | S37: UPI | T37: Marketplace | U37: Delivered | V37: 6 | W37: 4
A38: TNORD0037 | B38: TNCUST0088 | C38: 45847 | D38: Hosur | E38: Krishnagiri | F38: Male | G38: 50 | H38: 46-55 | I38: Sports | J38: Football | K38: 1 | L38: 736 | M38: 10 | N38: =Table1[[#This Row],[Discount]]/100 -> 0.1 | O38: 73.6 | P38: 662.4 | Q38: 189 | R38: 851.4 | S38: Cash on Delivery | T38: Website | U38: Delivered | V38: 1 | W38: 5
A39: TNORD0038 | B39: TNCUST0069 | C39: 45881 | D39: Erode | E39: Erode | F39: Female | G39: 55 | H39: 26-35 | I39: Home & Kitchen | J39: Water Bottle | K39: 2 | L39: 8848 | M39: 20 | N39: =Table1[[#This Row],[Discount]]/100 -> 0.2 | O39: 3539.2 | P39: 14156.8 | Q39: 139 | R39: 14295.8 | S39: UPI | T39: Mobile App | U39: Processing
A40: TNORD0039 | B40: TNCUST0180 | C40: 45790 | D40: Karur | E40: Karur | F40: Female | G40: 35 | H40: 56+ | I40: Grocery | J40: Cooking Oil | K40: 4 | L40: 2104 | M40: 5 | N40: =Table1[[#This Row],[Discount]]/100 -> 0.05 | O40: 420.8 | P40: 7995.2 | Q40: 110 | R40: 8105.2 | S40: UPI | T40: Marketplace | U40: Delivered | V40: 3 | W40: 4.5
...

Sheet DASHBOARD
A1: TAMIL NADU E-COMMERCE SALES DASHBOARD
A4: Sales Performance | Customer Insights | Order Analytics
A5: TOTAL SALES | D5: TOTAL ORDERS | G5: TOTAL QUANTITY | J5: AVERAGE RATING | P5: AVERAGE DELIVERY DAYS
A7: =GETPIVOTDATA("Total Sales",KPI!$B$1) -> 11906291 | D7: =GETPIVOTDATA("Total Orders",KPI!$B$1) -> 500 | G7: =GETPIVOTDATA("Total Quantity",KPI!$B$1) -> 1465 | J7: =GETPIVOTDATA("Average of Customer_Rating",KPI!$B$1) -> 4.0217391 | P7: =GETPIVOTDATA("Average of Delivery_Days",KPI!$B$1) -> 4.1066998

Sheet KPI
B1: Total Sales | C1: Total Orders | D1: Total Quantity | E1: Average of Customer_Rating | F1: Average of Delivery_Days
B2: 11906291 | C2: 500 | D2: 1465 | E2: 4.0217391 | F2: 4.1066998

Sheet MONTHLY SALES
B1: Row Labels | C1: Sum of Total_Amount_INR
B2: Jan | C2: 721624.45
B3: Feb | C3: 1053649.8
B4: Mar | C4: 969015.8
B5: Apr | C5: 1364396.9
B6: May | C6: 572779.65
B7: Jun | C7: 999373.4
B8: Jul | C8: 1005396.7
B9: Aug | C9: 855858.5
B10: Sep | C10: 1032071.7
B11: Oct | C11: 850444.8
B12: Nov | C12: 1413337.7
B13: Dec | C13: 1068341.3

Sheet SALES BY DISTRICT
B2: Row Labels | C2: Sum of Total_Amount_INR
B3: Thoothukudi | C3: 524669.45
B4: Thanjavur | C4: 563004.4
B5: Erode | C5: 586757.05
B6: Coimbatore | C6: 665104.4
B7: Karur | C7: 685587.4
B8: Madurai | C8: 750639.05
B9: Krishnagiri | C9: 783924.05
B10: Chennai | C10: 787029.5
B11: Vellore | C11: 793705.05
B12: Dindigul | C12: 851169.15
B13: Salem | C13: 889477.15
B14: Kanyakumari | C14: 905518.75
... B17: Tiruchirappalli | C17: 1109699.6

Sheet SALES BY CATEGORY
B2: Row Labels | C2: Sum of Total_Amount_INR
B3: Beauty | C3: 561426.65
B4: Electronics | C4: 8377695.1
B5: Fashion | C5: 714690.45
B6: Grocery | C6: 292016.4
B7: Home & Kitchen | C7: 889499.15
B8: Sports | C8: 1070963.1

Sheet ORDER STATUS
C2: Count of Order_ID
B3: Cancelled | C3: 25
B4: Delivered | C4: 322
B5: Processing | C5: 40
B6: Returned | C6: 32
B7: Shipped | C7: 81

Sheet PAYMENT METHOD
B2: Row Labels | C2: Count of Order_ID
B3: Cash on Delivery | C3: 87
B4: Credit Card | C4: 77
B5: Debit Card | C5: 80
B6: Net Banking | C6: 72
B7: UPI | C7: 100
B8: Wallet | C8: 84

Sheet SALES CHANNEL
B2: Row Labels | C2: Sum of Total_Amount_INR
B3: Marketplace | C3: 3883322.4
B4: Mobile App | C4: 4864974.1
B5: Website | C5: 3157994.4

Sheet TOP PRODUCTS
B2: Row Labels | C2: Sum of Total_Amount_INR
B3: Smartphone | C3: 2355279.4
B4: Laptop | C4: 1852230.4
B5: Headphones | C5: 1596624.6
B6: Smartwatch | C6: 1373061.2
B7: Power Bank | C7: 1200499.4
B8: Football | C8: 311284.95
B9: Badminton Racket | C9: 256863.35
B10: Mixer Grinder | C10: 242258.15
B11: Cookware Set | C11: 238310.8
B12: Jeans | C12: 202676.8
